#VRML_SIM R2023b utf8

EXTERNPROTO "https://raw.githubusercontent.com/cyberbotics/webots/R2023b/projects/objects/backgrounds/protos/TexturedBackground.proto"
EXTERNPROTO "https://raw.githubusercontent.com/cyberbotics/webots/R2023b/projects/objects/backgrounds/protos/TexturedBackgroundLight.proto"
EXTERNPROTO "https://raw.githubusercontent.com/cyberbotics/webots/R2023b/projects/objects/floors/protos/RectangleArena.proto"
EXTERNPROTO "https://raw.githubusercontent.com/cyberbotics/webots/R2023b/projects/robots/mir/mir100/protos/Mir100UltrasonicSensor.proto"
EXTERNPROTO "https://raw.githubusercontent.com/cyberbotics/webots/R2023b/projects/objects/solids/protos/SolidTorus.proto"

WorldInfo {
}
Viewpoint {
  orientation -0.080423609606841 0.16379201052120138 0.9832111778795178 1.3878372023304042
  position -1.844763206048669 -3.17015997548972 1.2550815986510244
}
TexturedBackground {
}
TexturedBackgroundLight {
}
RectangleArena {
  floorSize 3 2
}
DEF falcon Robot {
  translation -1.32 -0.5 0
  children [
    Pose {
      children [
        DEF otaceni HingeJoint {
          jointParameters HingeJointParameters {
            axis 0 0 1
            anchor 0.22 0 0.075
          }
          device [
            PositionSensor {
            }
            DEF ram0 RotationalMotor {
              name "ram0"
            }
          ]
          endPoint Solid {
            translation 0.22 0 0.075
            children [
              DEF ram1_2 HingeJoint {
                jointParameters HingeJointParameters {
                  axis 0 1 0
                  anchor -0.025 0 0.1
                }
                device [
                  PositionSensor {
                  }
                  DEF ram1 RotationalMotor {
                    name "ram1"
                  }
                ]
                endPoint Solid {
                  translation -0.004999999999999893 0 0.15
                  rotation 0 1 0 0
                  children [
                    DEF ram2_3 HingeJoint {
                      jointParameters HingeJointParameters {
                        axis 0 1 0
                        anchor 0 0 0.05
                      }
                      device [
                        PositionSensor {
                        }
                        DEF ram2 RotationalMotor {
                          name "ram2"
                        }
                      ]
                      endPoint Solid {
                        translation -1.0424269302054433e-11 0 0.1
                        rotation 0 1 0 0
                        children [
                          DEF gripper VacuumGripper {
                            translation 0 0 0.05
                            children [
                              DEF bobik SolidTorus {
                                translation 0 0 0.005
                                majorRadius 0.01
                                minorRadius 0.005
                                appearance PBRAppearance {
                                  baseColor 0 0 0
                                  baseColorMap ImageTexture {
                                    url [
                                      "https://raw.githubusercontent.com/cyberbotics/webots/R2023b/projects/default/worlds/textures/tagged_wall.jpg"
                                    ]
                                  }
                                  roughness 0.5
                                  metalness 0
                                }
                              }
                            ]
                            name "gripper"
                            physics Physics {
                              density -1
                              mass 0.003
                            }
                          }
                          DEF rameno2 Shape {
                            appearance PBRAppearance {
                              baseColor 0.752941 0.380392 0.796078
                              metalness 0
                            }
                            geometry Box {
                              size 0.03 0.05 0.09
                            }
                          }
                        ]
                        name "solid(1)"
                        boundingObject USE rameno2
                        physics Physics {
                          density -1
                          mass 0.05
                        }
                      }
                    }
                    DEF rameno2 Shape {
                      appearance PBRAppearance {
                        baseColor 0.752941 0.380392 0.796078
                        metalness 0
                      }
                      geometry Box {
                        size 0.04 0.05 0.09
                      }
                    }
                  ]
                  name "solid(1)"
                  boundingObject USE rameno2
                  physics Physics {
                    density -1
                    mass 0.12
                  }
                }
              }
              DEF rameno_1 Solid {
                translation 0 0 0.05
                children [
                  DEF rameno1 Shape {
                    appearance PBRAppearance {
                      baseColor 0.752941 0.380392 0.796078
                      metalness 0
                    }
                    geometry Box {
                      size 0.05 0.05 0.09
                    }
                  }
                ]
                boundingObject USE rameno1
                physics Physics {
                }
              }
              DEF podstava Shape {
                appearance PBRAppearance {
                  baseColor 0.964706 0.827451 0.176471
                }
                geometry Cylinder {
                  height 0.01
                  radius 0.04
                }
              }
            ]
            name "solid(8)"
            boundingObject USE podstava
            physics Physics {
              density -1
              mass 0.2
            }
          }
        }
        DEF DS DistanceSensor {
          translation 0.24 0.089 0.035
          rotation 0 0 1 1.5708
          children [
            DEF ds_box Shape {
              appearance PBRAppearance {
              }
              geometry Box {
                size 0.0025 0.047 0.025
              }
            }
            DEF ds_senzor Mir100UltrasonicSensor {
              translation -0.008 0 0
              rotation 0 0 -1 -5.307179586466759e-06
              lookupTable [
                0.01 0 2.5
                0.35 0 0
              ]
            }
          ]
          boundingObject USE ds_box
          physics Physics {
            density -1
            mass 0.01
          }
          lookupTable [
            0 0 0
            1 1000 0
          ]
        }
        DEF kulicka BallJoint {
          jointParameters BallJointParameters {
            anchor -0.05 0 0.01
          }
          jointParameters2 JointParameters {
            axis 1 1 1
          }
          endPoint Solid {
            translation -0.050575987438896824 0.0009666442097727026 0.009183602863165895
            rotation -0.14015147845362794 0.7968594437289697 0.5876840903301872 3.7292179224786364
            children [
              DEF kulicka Shape {
                appearance PBRAppearance {
                  baseColor 0.603922 0.6 0.588235
                }
                geometry Sphere {
                  radius 0.01
                }
              }
            ]
            name "solid(6)"
            boundingObject USE kulicka
            physics Physics {
              density -1
              mass 0.01
            }
          }
        }
        DEF kulicka BallJoint {
          jointParameters BallJointParameters {
            anchor 0.26 0 0.01
          }
          jointParameters2 JointParameters {
            axis 1 1 1
          }
          endPoint Solid {
            translation 0.26 0 0.01
            children [
              DEF kulicka Shape {
                appearance PBRAppearance {
                  baseColor 0.603922 0.6 0.588235
                }
                geometry Sphere {
                  radius 0.01
                }
              }
            ]
            name "solid(7)"
            boundingObject USE kulicka
            physics Physics {
              density -1
              mass 0.01
            }
          }
        }
        DEF kolo_R HingeJoint {
          jointParameters HingeJointParameters {
            axis 0 1 0
            anchor 0.105 -0.08 0.032
          }
          device [
            RotationalMotor {
              name "mR"
            }
            PositionSensor {
              name "posR"
            }
          ]
          endPoint Solid {
            translation 0.105 -0.08 0.03
            rotation -0.9998985982481238 -0.010119875356725027 -0.010019049066743583 4.694136835524987
            children [
              DEF kolo Shape {
                appearance PBRAppearance {
                  baseColor 0.878431 0.105882 0.141176
                  metalness 0
                }
                geometry Cylinder {
                  height 0.01
                  radius 0.03
                }
              }
            ]
            name "solid(4)"
            boundingObject USE kolo
            physics Physics {
              density -1
              mass 0.05
            }
          }
        }
        DEF kolo_L HingeJoint {
          jointParameters HingeJointParameters {
            axis 0 1 0
            anchor 0.105 0.08 0.0319984
          }
          device [
            RotationalMotor {
              name "mL"
            }
            PositionSensor {
              name "posL"
            }
          ]
          endPoint Solid {
            translation 0.105 0.08 0.03
            rotation -0.9999880376834208 -0.003450128615862139 -0.0034671461745183377 4.691419563705206
            children [
              DEF kolo Shape {
                appearance PBRAppearance {
                  baseColor 0.878431 0.105882 0.141176
                  metalness 0
                }
                geometry Cylinder {
                  height 0.01
                  radius 0.03
                }
              }
            ]
            name "solid(5)"
            boundingObject USE kolo
            physics Physics {
              density -1
              mass 0.05
            }
          }
        }
        DEF zadek Solid {
          translation 0 0 0.04
          children [
            DEF zadek Shape {
              appearance PBRAppearance {
                baseColor 0 0 0
              }
              geometry Box {
                size 0.14 0.18 0.045
              }
            }
          ]
          boundingObject USE zadek
          physics Physics {
            density -1
            mass 0.4
          }
        }
        DEF vrch Solid {
          translation 0.105 0 0.065
          children [
            DEF vrch Shape {
              appearance PBRAppearance {
                baseColor 0.141176 0.121569 0.192157
              }
              geometry Box {
                size 0.35 0.18 0.005
              }
            }
          ]
          name "solid(3)"
          boundingObject USE vrch
          physics Physics {
            density -1
            mass 0.2
          }
        }
        DEF predek Solid {
          translation 0.21 0 0.04
          children [
            DEF predek Shape {
              appearance PBRAppearance {
                baseColor 0 0 0
              }
              geometry Box {
                size 0.14 0.18 0.045
              }
            }
          ]
          name "solid(1)"
          boundingObject USE predek
          physics Physics {
            density -1
            mass 0.4
          }
        }
        DEF moroty Solid {
          translation 0.105 0 0.04
          children [
            DEF mortory Shape {
              appearance PBRAppearance {
                baseColor 0.368627 0.360784 0.392157
              }
              geometry Box {
                size 0.07 0.15 0.045
              }
            }
          ]
          name "solid(2)"
          boundingObject USE mortory
          physics Physics {
            density -1
            mass 0.7
          }
        }
      ]
    }
  ]
  physics Physics {
    density -1
    mass 2
  }
  controller "Falcon_lib"
  selfCollision TRUE
}
Robot {
  translation -1.08191 0.174483 0.0901
  rotation 0 0 1 0.261799
  children [
    DEF nakaldak Pose {
      children [
        DEF naklad Solid {
          translation 0.07 0.17 0
          children [
            DEF nakald Shape {
              appearance PBRAppearance {
                baseColor 0.101961 0.372549 0.705882
                metalness 0
              }
              geometry Box {
                size 0.06 0.24 0.18
              }
            }
          ]
          name "naklad(1)"
          boundingObject USE nakald
          physics Physics {
            density -1
            mass 0.5
          }
        }
        DEF kabina Solid {
          children [
            DEF kabina Shape {
              appearance PBRAppearance {
                baseColor 0.101961 0.372549 0.705882
                metalness 0
              }
              geometry Box {
                size 0.2 0.1 0.18
              }
            }
          ]
          name "solid(1)"
          boundingObject USE kabina
          physics Physics {
            density -1
            mass 0.2
          }
        }
      ]
    }
  ]
  name "havarovany_nakladak"
  boundingObject USE kabina
  physics Physics {
    density -1
    mass 0.7
  }
}
Robot {
  translation 0.244577 0.943055 0.1001
  rotation 0.7071082811855307 -2.510550998334532e-07 -0.7071052811843378 3.14159
  children [
    DEF nakaldak Pose {
      children [
        DEF naklad Solid {
          translation 0.07 0.17 0
          children [
            DEF nakald Shape {
              appearance PBRAppearance {
                baseColor 0.101961 0.372549 0.705882
                metalness 0
              }
              geometry Box {
                size 0.06 0.24 0.18
              }
            }
          ]
          name "naklad(1)"
          boundingObject USE nakald
          physics Physics {
            density -1
            mass 0.5
          }
        }
        DEF kabina Solid {
          children [
            DEF kabina Shape {
              appearance PBRAppearance {
                baseColor 0.101961 0.372549 0.705882
                metalness 0
              }
              geometry Box {
                size 0.2 0.1 0.18
              }
            }
          ]
          name "solid(1)"
          boundingObject USE kabina
          physics Physics {
            density -1
            mass 0.2
          }
        }
      ]
    }
  ]
  name "nakladak"
  boundingObject USE kabina
  physics Physics {
    density -1
    mass 0.7
  }
  locked TRUE
  translationStep 0
  rotationStep 0
}
DEF naklad_1 Solid {
  translation -1.33 0.16 0.0305
  rotation 0 0 1 0.523599
  children [
    DEF kostka Shape {
      appearance PBRAppearance {
        baseColor 0.14902 0.635294 0.411765
        metalness 0
      }
      geometry Box {
        size 0.06 0.06 0.06
      }
    }
  ]
  boundingObject USE kostka
  physics Physics {
    density -1
    mass 0.3
  }
}
DEF naklad_2 Solid {
  translation -1.31098 0.0670591 0.0305
  rotation 0 0 1 -5.307179586466759e-06
  children [
    DEF kostka Shape {
      appearance PBRAppearance {
        baseColor 0.14902 0.635294 0.411765
        metalness 0
      }
      geometry Box {
        size 0.06 0.06 0.06
      }
    }
  ]
  name "solid(1)"
  boundingObject USE kostka
  physics Physics {
    density -1
    mass 0.3
  }
}
DEF naklad_3 Solid {
  translation -1.22036 0.0500953 0.0305
  rotation 0 0 -1 -0.261795307179586
  children [
    DEF kostka Shape {
      appearance PBRAppearance {
        baseColor 0.14902 0.635294 0.411765
        metalness 0
      }
      geometry Box {
        size 0.06 0.06 0.06
      }
    }
  ]
  name "solid(2)"
  boundingObject USE kostka
  physics Physics {
    density -1
    mass 0.15
  }
}
DEF naklad_3 Solid {
  translation -1.29722 -0.041087 0.0305
  rotation 0 0 -1 -1.3089953071795861
  children [
    DEF kostka Shape {
      appearance PBRAppearance {
        baseColor 0.14902 0.635294 0.411765
        metalness 0
      }
      geometry Box {
        size 0.06 0.06 0.06
      }
    }
  ]
  name "solid(5)"
  boundingObject USE kostka
  physics Physics {
    density -1
    mass 0.15
  }
}
DEF naklad_4 Solid {
  translation -1.39928 0.09 0.0305
  rotation 0 0 -1 4.692820414042842e-06
  children [
    DEF kostka Shape {
      appearance PBRAppearance {
        baseColor 0.14902 0.635294 0.411765
        metalness 0
      }
      geometry Box {
        size 0.06 0.06 0.06
      }
    }
  ]
  name "solid(3)"
  boundingObject USE kostka
  physics Physics {
    density -1
    mass 0.15
  }
}
DEF naklad_5 Solid {
  translation -1.39062 -0.0350001 0.0305
  rotation 0 0 1 -1.0472053071795866
  children [
    DEF kostka Shape {
      appearance PBRAppearance {
        baseColor 0.14902 0.635294 0.411765
        metalness 0
      }
      geometry Box {
        size 0.06 0.06 0.06
      }
    }
  ]
  name "solid(4)"
  boundingObject USE kostka
  physics Physics {
    density -1
    mass 0.15
  }
}
